{"uuid": "a5f54424-4083-4be0-bf8e-183900e0956c", "children": ["98e4e18b-66da-408c-96bb-72ef025d19fa"], "befores": [{"name": "chrome_init", "status": "passed", "start": 1652105543538, "stop": 1652105545161}], "afters": [{"name": "chrome_init::0", "status": "broken", "statusDetails": {"message": "selenium.common.exceptions.WebDriverException: Message: chrome not reachable\n  (Session info: chrome=101.0.4951.41)\n\n", "trace": "  File \"/usr/local/lib/python3.8/dist-packages/allure_commons/_allure.py\", line 200, in __call__\n    return self._fixture_function(*args, **kwargs)\n  File \"/home/c-sohans/.local/lib/python3.8/site-packages/_pytest/fixtures.py\", line 941, in _teardown_yield_fixture\n    next(it)\n  File \"/home/c-sohans/Desktop/ondemand-automation-ui/testCases/conftest.py\", line 92, in chrome_init\n    chrome_driver.close()\n  File \"/home/c-sohans/.local/lib/python3.8/site-packages/selenium/webdriver/remote/webdriver.py\", line 688, in close\n    self.execute(Command.CLOSE)\n  File \"/home/c-sohans/.local/lib/python3.8/site-packages/selenium/webdriver/remote/webdriver.py\", line 321, in execute\n    self.error_handler.check_response(response)\n  File \"/home/c-sohans/.local/lib/python3.8/site-packages/selenium/webdriver/remote/errorhandler.py\", line 242, in check_response\n    raise exception_class(message, screen, stacktrace)\n"}, "start": 1652105547599, "stop": 1652105547616}], "start": 1652105543538, "stop": 1652105547616}